Workbook

Sheet Summary
A1: Cheerio Assist — the numbers
A2: Start here. Every figure is a formula. Blue inputs live on Assumptions. North star: human tickets per 100 active businesses. Target for month 3 is the drop in row 8, not a round number chosen first.
A4: The queue | C4: The money
A5: Active businesses | B5: =Assumptions!C5 | C5: Cost of one human ticket | D5: =Cost!B7
A6: Queries this month | B6: =Volume!E9 | C6: Token cost of one Assist session | D6: =Cost!B11
A7: Human tickets per 100 businesses, today | B7: =Volume!B15 | C7: Full Assist cost per query it closes | D7: =Cost!B31
A8: Human tickets per 100 businesses, month 3 | B8: =Volume!B28 | C8: Support cost today | D8: =Cost!B23
A9: Drop in human tickets | B9: =Volume!B29 | C9: Support cost in month 3 | D9: =Cost!B25
C10: Saving per month | D10: =Cost!B26
A11: Month 1 drop | B11: =Roadmap!C19 | C11: Saving per rupee spent on Assist | D11: =Billing!B9
A12: Month 2 drop | B12: =Roadmap!D19 | C12: Free beats a ₹49 fee by | D12: =Billing!B33
A14: All structural checks | B14: =IF(COUNTIF(Audit!B6:B12,"ALERT")+COUNTIF(Audit!B16:B19,"ALERT")=0,"PASS","ALERT")
A16: Cost comparison for the chart
B17: Human payroll | C17: Assist operating cost
A18: Today | B18: =Cost!B23 | C18: =0
A19: Month 3, Assist included free | B19: =Cost!B24 | C19: =Cost!B18
A20: Month 3, if we charge ₹49 | B20: =Billing!B24 | C20: =Billing!B26
A38: Read the third bar as a warning, not a plan. The fee brings in revenue on the Billing sheet and still costs more overall, because human tickets come back. Sources worth knowing: OpenAI gpt-4o-mini prices (developers.openai.com/api/docs/pricing, 12 Oct 2026); USD/INR about 95.8 on 12 Oct 2026; Cheerio list prices and included calls on cheerio.ai/pricing the same day. Agent salary, query mix, resolution rates, and adoption are assumptions.

Sheet Assumptions
A1: Cheerio Assist — inputs
A2: Blue cells are the only inputs. Change them and Summary, Volume, Cost, Billing, Roadmap, and Audit all move. Black cells on the other sheets are formulas. Do not paste values over them. These volumes are a guesstimate. Cheerio did not publish ticket counts. If you have the export, replace the blue cells.
A4: Company
A5: Active businesses | C5: 5000 | D5: businesses | G5: Given in the brief. Treat as the businesses that log in during a month, not signups all-time.
A6: Already solved with no human, before Assist | C6: 0.08 | D6: share of queries | G6: Help docs already exist, so not every query becomes a ticket today. 8% is a judgment, not a measurement.
A7: Month-3 share of queries that open Assist | C7: 0.7 | D7: share of queries | G7: The other 30% still email or WhatsApp the support line and never see the panel.
A9: Who raises the queries
A10: Segment | B10: Share of businesses | C10: Queries per business / month | G10: Why this query rate
A11: Onboarding or a new channel | B11: 0.2 | C11: 2.5 | G11: First 45 days, or they added a channel this month. Setup, first template, first workflow.
A12: Steady weekly use | B12: 0.65 | C12: 1 | G12: A campaign, a template, or a silent bot in a typical month. Not every week.
A13: Light or seasonal | B13: 0.15 | C13: 0.4 | G13: They pay, they rarely log in. A bill or a login problem a couple of times a year.
A14: Shares must equal 100% | B14: =SUM(B11:B13) | G14: =IF(ABS(B14-1)<0.0001,"OK","Fix the shares. They have to sum to 100%.")
A16: What the queries are, and how many Assist can finish
A17: Issue | B17: Share of queries | C17: Playbook can finish | D17: Live in month 1 | E17: Live in month 2 | F17: Live in month 3 | G17: What the rate means
A18: Template rejected | B18: 0.26 | C18: 0.72 | D18: 1 | E18: 1 | F18: 1 | G18: Name format, Utility vs Marketing, missing variable example. A second rejection goes to a person. I would not let Assist keep editing.
A19: WhatsApp setup stuck | B19: 0.2 | C19: 0.48 | D19: 0 | E19: 1 | F19: 1 | G19: Assist can show the incomplete step. It cannot make someone a Facebook admin, or free a number that is still on the WhatsApp app.
A20: Workflow did not reply | B20: 0.16 | C20: 0.62 | D20: 0 | E20: 0 | F20: 1 | G20: Toggle off, keyword does not match, or the template is not approved. Redesigning the flow stays with a person.
A21: Campaign did not send | B21: 0.12 | C21: 0.75 | D21: 1 | E21: 1 | F21: 1 | G21: Usually the template. Status is a fact Assist can show. This is separate from a money question.
A22: Why was I charged? | B22: 0.06 | C22: 0.1 | D22: 1 | E22: 1 | F22: 1 | G22: Assist explains the debit and stops. Almost everyone with a money question still wants a person. 10% accept the explanation.
A23: Integration not syncing | B23: 0.1 | C23: 0.35 | D23: 0 | E23: 0 | F23: 1 | G23: Empty Shopify connection or blank webhook is checkable. The other company's error is not.
A24: Other | B24: 0.1 | C24: 0.1 | D24: 0 | E24: 0 | F24: 1 | G24: Bugs, access, and one-off asks. A playbook should barely touch these.
A25: Shares must equal 100% | B25: =SUM(B18:B24) | G25: =IF(ABS(B25-1)<0.0001,"OK","Fix the shares. They have to sum to 100%.")
A27: Human support
A28: Agent monthly CTC | C28: 40000 | D28: INR / month | G28: Assumption for an L1 agent. Not a salary survey. Edit it.
A29: Load for benefits, tools, and a lead's time | C29: 0.2 | D29: share of CTC | G29: Loaded cost = CTC × (1 + this).
A30: Tickets one agent finishes in a day | C30: 10 | D30: tickets | G30: How-to tickets. Deep bugs are slower. If you believe 8, type 8.
A31: Working days in a month | C31: 22 | D31: days
A33: Model — gpt-4o-mini
A34: Prices from OpenAI's API pricing page, checked 12 Oct 2026: gpt-4o-mini input $0.15, cached input $0.075, output $0.60 per 1M tokens. https://developers.openai.com/api/docs/pricing — USD/INR is the 12 Oct 2026 market, about ₹95.75 to ₹95.83 per dollar. Both are inputs.
A35: Input price | C35: 0.15 | D35: USD per 1M tokens
A36: Cached input price | C36: 0.075 | D36: USD per 1M tokens
A37: Output price | C37: 0.6 | D37: USD per 1M tokens
A38: Rupees per US dollar | C38: 95.8 | D38: INR
A39: Cached tokens per session | C39: 2500 | D39: tokens | G39: Playbook text plus a short account snapshot. Cached because the playbook repeats across sessions.
A40: Fresh input tokens per session | C40: 900 | D40: tokens | G40: The user's words plus the live status that changed this session.
A41: Output tokens per session | C41: 450 | D41: tokens
A42: Share of sessions with a follow-up turn | C42: 0.2 | D42: share
A43: Follow-up fresh input tokens | C43: 600 | D43: tokens
A44: Follow-up output tokens | C44: 350 | D44: tokens
A46: Other monthly cost
...

Sheet Volume
A1: Query volume
A2: Every number on this sheet is a formula pointed at Assumptions. A query becomes a human ticket unless someone finishes it with no ticket. Today that is only the unaided share. In month 3 it is the unaided share for people who never open Assist, plus the playbook for people who do.
A4: Queries this month
A5: Segment | B5: Share of businesses | C5: Businesses | D5: Queries per business | E5: Queries
A6: =Assumptions!A11 | B6: =Assumptions!B11 | C6: =Assumptions!$C$5*B6 | D6: =Assumptions!C11 | E6: =C6*D6
A7: =Assumptions!A12 | B7: =Assumptions!B12 | C7: =Assumptions!$C$5*B7 | D7: =Assumptions!C12 | E7: =C7*D7
A8: =Assumptions!A13 | B8: =Assumptions!B13 | C8: =Assumptions!$C$5*B8 | D8: =Assumptions!C13 | E8: =C8*D8
A9: Total | B9: =SUM(B6:B8) | C9: =SUM(C6:C8) | E9: =SUM(E6:E8)
A11: Today, before Assist
A12: Queries | B12: =E9 | E12: From the segments above.
A13: Already closed with no human | B13: =B12*Assumptions!C6 | E13: The 8% (or whatever you typed).
A14: Human tickets | B14: =B12-B13 | E14: This is the queue.
A15: Human tickets per 100 active businesses | B15: =B14/Assumptions!C5*100 | E15: North star, today.
A17: Month 3, with Assist
A18: Issue | B18: Queries | C18: Playbook finish rate | D18: Adoption on this issue | E18: Share closed with no human | F18: Closed with no human | G18: Human tickets | H18: Closed by Assist itself
A19: =Assumptions!A18 | B19: =$E$9*Assumptions!B18 | C19: =Assumptions!C18 | D19: =Assumptions!$C$7*Assumptions!F18 | E19: =(1-D19)*Assumptions!$C$6+D19*C19 | F19: =B19*E19 | G19: =B19-F19 | H19: =B19*D19*C19
A20: =Assumptions!A19 | B20: =$E$9*Assumptions!B19 | C20: =Assumptions!C19 | D20: =Assumptions!$C$7*Assumptions!F19 | E20: =(1-D20)*Assumptions!$C$6+D20*C20 | F20: =B20*E20 | G20: =B20-F20 | H20: =B20*D20*C20
A21: =Assumptions!A20 | B21: =$E$9*Assumptions!B20 | C21: =Assumptions!C20 | D21: =Assumptions!$C$7*Assumptions!F20 | E21: =(1-D21)*Assumptions!$C$6+D21*C21 | F21: =B21*E21 | G21: =B21-F21 | H21: =B21*D21*C21
A22: =Assumptions!A21 | B22: =$E$9*Assumptions!B21 | C22: =Assumptions!C21 | D22: =Assumptions!$C$7*Assumptions!F21 | E22: =(1-D22)*Assumptions!$C$6+D22*C22 | F22: =B22*E22 | G22: =B22-F22 | H22: =B22*D22*C22
A23: =Assumptions!A22 | B23: =$E$9*Assumptions!B22 | C23: =Assumptions!C22 | D23: =Assumptions!$C$7*Assumptions!F22 | E23: =(1-D23)*Assumptions!$C$6+D23*C23 | F23: =B23*E23 | G23: =B23-F23 | H23: =B23*D23*C23
A24: =Assumptions!A23 | B24: =$E$9*Assumptions!B23 | C24: =Assumptions!C23 | D24: =Assumptions!$C$7*Assumptions!F23 | E24: =(1-D24)*Assumptions!$C$6+D24*C24 | F24: =B24*E24 | G24: =B24-F24 | H24: =B24*D24*C24
A25: =Assumptions!A24 | B25: =$E$9*Assumptions!B24 | C25: =Assumptions!C24 | D25: =Assumptions!$C$7*Assumptions!F24 | E25: =(1-D25)*Assumptions!$C$6+D25*C25 | F25: =B25*E25 | G25: =B25-F25 | H25: =B25*D25*C25
A26: Month 3 total | B26: =SUM(B19:B25) | F26: =SUM(F19:F25) | G26: =SUM(G19:G25) | H26: =SUM(H19:H25)
A28: Human tickets per 100 businesses, month 3 | B28: =G26/Assumptions!C5*100
A29: Drop in human tickets vs today | B29: =(B14-G26)/B14
A30: Queries closed by Assist itself | B30: =H26
A31: Sessions that open Assist (we pay tokens on these) | B31: =E9*Assumptions!C7
A33: Share closed with no human = (1 − adoption) × unaided rate + adoption × playbook rate. People who never open Assist keep today's unaided rate. People who open it get the playbook rate instead, not on top. Closed by Assist itself = queries × adoption × playbook rate. That is the slice we compare with a human agent.

Sheet Cost
A1: What it costs to run, versus agents
A2: Token math is here because the brief asks for it. It is not the decision. The playbook owner and the agents we still need are the decision. Fractional FTE is the fair comparison. Whole people are who you would actually roster. Both are shown.
A4: One human ticket
A5: Loaded cost of one agent per month | B5: =Assumptions!C28*(1+Assumptions!C29) | C5: CTC × (1 + load).
A6: Tickets one agent finishes in a month | B6: =Assumptions!C30*Assumptions!C31 | C6: Days × tickets per day.
A7: Cost of one human ticket | B7: =B5/B6 | C7: This is the number Assist has to beat.
A9: Tokens
A10: USD per Assist session | B10: =Assumptions!C39/1000000*Assumptions!C36+Assumptions!C40/1000000*Assumptions!C35+Assumptions!C41/1000000*Assumptions!C37+Assumptions!C42*(Assumptions!C43/1000000*Assumptions!C35+Assumptions!C44/1000000*Assumptions!C37) | C10: Cached tokens at the cached price, fresh tokens at the input price, output at the output price, plus a follow-up on some sessions.
A11: INR per Assist session | B11: =B10*Assumptions!C38
A12: Sessions in month 3 | B12: =Volume!B31 | C12: One session per query that opens Assist, including the ones a person still has to finish.
A13: Token bill in month 3 | B13: =B12*B11
A15: Assist, fully loaded, month 3
A16: Hosting, logs, and search | B16: =Assumptions!C47
A17: Playbook owner | B17: =Assumptions!C48
A18: Assist operating cost | B18: =B13+B16+B17 | C18: Tokens + hosting + the owner.
A20: Company cost — fractional load
A21: Agent load today, FTE | B21: =Volume!B14/B6 | C21: Human tickets today ÷ monthly capacity.
A22: Agent load in month 3, FTE | B22: =Volume!G26/B6 | C22: Tickets Assist did not close.
A23: Human payroll today | B23: =B21*B5
A24: Human payroll in month 3 | B24: =B22*B5
A25: Total support cost in month 3 | B25: =B24+B18 | C25: Remaining agents + Assist operating cost.
A26: Monthly saving vs today | B26: =B23-B25 | C26: The number I would manage the quarter against.
A28: Same volume, two ways of finishing it
A29: Same volume means the queries Assist itself closes. Human cost uses the per-ticket rate. Assist cost loads the entire operating bill onto that slice, tokens included. A portion of those users might have coped with the docs anyway. The company saving in row 26 already nets that out. This block is the unit comparison the brief asks for.
A30: Queries Assist closes | B30: =Volume!H26
A31: Assist cost per one of those | B31: =B18/B30 | C31: Full operating cost ÷ Assist closures.
A32: Human cost for the same queries | B32: =B30*B7
A33: Difference on that slice | B33: =B32-B18 | C33: Human cost minus the whole Assist bill.
A35: If you can only hire whole people
A36: Agents to roster today | B36: =CEILING(B21,1) | C36: Rounded up.
A37: Agents to roster in month 3 | B37: =CEILING(B22,1) | C37: Rounded up. Do not drop headcount until the ticket rate actually moves.
A38: Payroll today, whole people | B38: =B36*B5
A39: Month-3 cost, whole people + Assist | B39: =B37*B5+B18
A40: Saving, whole people | B40: =B38-B39
A42: Meta's WhatsApp message rates are not in this sheet. Assist does not send those messages. A search summary called a dollar rate card a rupee rate. I left it out rather than build a margin on a mislabeled number.

Sheet Roadmap
A1: How the 3-month move actually happens
A2: Month 1 is only the failed campaign and the template behind it, plus the charge question on that same screen. Month 2 adds WhatsApp setup. Month 3 adds workflows and a thin pass at integrations and everything else. Adoption is an input on Assumptions. Issues that are not live that month stay at today's unaided rate.
A4: Per issue
A5: Issue | B5: Queries | C5: Month 1 human tickets | D5: Month 2 human tickets | E5: Month 3 human tickets | F5: Month 1 adoption used | G5: Month 2 adoption used | H5: Month 3 adoption used
A6: =Assumptions!A18 | B6: =Volume!B19 | C6: =B6*(1-((1-F6)*Assumptions!$C$6+F6*Assumptions!C18)) | D6: =B6*(1-((1-G6)*Assumptions!$C$6+G6*Assumptions!C18)) | E6: =B6*(1-((1-H6)*Assumptions!$C$6+H6*Assumptions!C18)) | F6: =Assumptions!$C$57*Assumptions!D18 | G6: =Assumptions!$C$58*Assumptions!E18 | H6: =Assumptions!$C$59*Assumptions!F18
A7: =Assumptions!A19 | B7: =Volume!B20 | C7: =B7*(1-((1-F7)*Assumptions!$C$6+F7*Assumptions!C19)) | D7: =B7*(1-((1-G7)*Assumptions!$C$6+G7*Assumptions!C19)) | E7: =B7*(1-((1-H7)*Assumptions!$C$6+H7*Assumptions!C19)) | F7: =Assumptions!$C$57*Assumptions!D19 | G7: =Assumptions!$C$58*Assumptions!E19 | H7: =Assumptions!$C$59*Assumptions!F19
A8: =Assumptions!A20 | B8: =Volume!B21 | C8: =B8*(1-((1-F8)*Assumptions!$C$6+F8*Assumptions!C20)) | D8: =B8*(1-((1-G8)*Assumptions!$C$6+G8*Assumptions!C20)) | E8: =B8*(1-((1-H8)*Assumptions!$C$6+H8*Assumptions!C20)) | F8: =Assumptions!$C$57*Assumptions!D20 | G8: =Assumptions!$C$58*Assumptions!E20 | H8: =Assumptions!$C$59*Assumptions!F20
A9: =Assumptions!A21 | B9: =Volume!B22 | C9: =B9*(1-((1-F9)*Assumptions!$C$6+F9*Assumptions!C21)) | D9: =B9*(1-((1-G9)*Assumptions!$C$6+G9*Assumptions!C21)) | E9: =B9*(1-((1-H9)*Assumptions!$C$6+H9*Assumptions!C21)) | F9: =Assumptions!$C$57*Assumptions!D21 | G9: =Assumptions!$C$58*Assumptions!E21 | H9: =Assumptions!$C$59*Assumptions!F21
A10: =Assumptions!A22 | B10: =Volume!B23 | C10: =B10*(1-((1-F10)*Assumptions!$C$6+F10*Assumptions!C22)) | D10: =B10*(1-((1-G10)*Assumptions!$C$6+G10*Assumptions!C22)) | E10: =B10*(1-((1-H10)*Assumptions!$C$6+H10*Assumptions!C22)) | F10: =Assumptions!$C$57*Assumptions!D22 | G10: =Assumptions!$C$58*Assumptions!E22 | H10: =Assumptions!$C$59*Assumptions!F22
A11: =Assumptions!A23 | B11: =Volume!B24 | C11: =B11*(1-((1-F11)*Assumptions!$C$6+F11*Assumptions!C23)) | D11: =B11*(1-((1-G11)*Assumptions!$C$6+G11*Assumptions!C23)) | E11: =B11*(1-((1-H11)*Assumptions!$C$6+H11*Assumptions!C23)) | F11: =Assumptions!$C$57*Assumptions!D23 | G11: =Assumptions!$C$58*Assumptions!E23 | H11: =Assumptions!$C$59*Assumptions!F23
A12: =Assumptions!A24 | B12: =Volume!B25 | C12: =B12*(1-((1-F12)*Assumptions!$C$6+F12*Assumptions!C24)) | D12: =B12*(1-((1-G12)*Assumptions!$C$6+G12*Assumptions!C24)) | E12: =B12*(1-((1-H12)*Assumptions!$C$6+H12*Assumptions!C24)) | F12: =Assumptions!$C$57*Assumptions!D24 | G12: =Assumptions!$C$58*Assumptions!E24 | H12: =Assumptions!$C$59*Assumptions!F24
A13: Total human tickets | B13: =SUM(B6:B12) | C13: =SUM(C6:C12) | D13: =SUM(D6:D12) | E13: =SUM(E6:E12)
A15: Against today
B16: Today | C16: Month 1 | D16: Month 2 | E16: Month 3
A17: Human tickets | B17: =Volume!B14 | C17: =C13 | D17: =D13 | E17: =E13
A18: Per 100 active businesses | B18: =B17/Assumptions!$C$5*100 | C18: =C17/Assumptions!$C$5*100 | D18: =D17/Assumptions!$C$5*100 | E18: =E17/Assumptions!$C$5*100
A19: Drop vs today | B19: =0 | C19: =(B17-C17)/B17 | D19: =(B17-D17)/B17 | E19: =(B17-E17)/B17
A21: Month 3 on this sheet matches Volume | B21: =IF(ABS(E13-Volume!G26)<0.05,"PASS","ALERT")
A23: Gate for the quarter: if month 1 does not cut human tickets by about 10%, do not start the setup playbook. Fix the campaign screen first. The 10% is a management rule, not a formula. Month 1 in this model is a bit above that, which is why month 2 is allowed.

Sheet Billing
A1: How to charge
A2: Include Assist on every paid plan. Do not sell it per conversation, per credit, or as a bot add-on. Growth already includes 4 support calls a month and Pro includes 10 (cheerio.ai/pricing, checked 12 Oct 2026). Escalation uses that entitlement. A new fee on the fix trains the owner to skip it and message a person, which is the path that costs about ₹218.
A4: Free Assist — company outcome vs doing nothing
A5: Human payroll today | B5: =Cost!B23
A6: Month-3 total (agents still needed + Assist) | B6: =Cost!B25
A7: Net saving per month | B7: =B5-B6 | C7: This is the margin. It is payroll you do not add, not a new line of revenue.
A8: Assist operating cost | B8: =Cost!B18
A9: Saving per rupee of Assist cost | B9: =IF(B8=0,"n/a",B7/B8) | C9: Above 1 means the operating cost comes back as avoided payroll.
A11: If we metered it anyway
A12: Fee and the lower adoption are inputs on Assumptions (the blue cells under “The price I would not charge”). Every issue is live, same as month 3. Only adoption changes. Hosting and the playbook owner stay, because you still run the system.
A14: Issue | B14: Human tickets if metered | C14: Assist closures if metered
A15: =Assumptions!A18 | B15: =Volume!B19*(1-((1-Assumptions!$C$54)*Assumptions!$C$6+Assumptions!$C$54*Assumptions!C18)) | C15: =Volume!B19*Assumptions!$C$54*Assumptions!C18
A16: =Assumptions!A19 | B16: =Volume!B20*(1-((1-Assumptions!$C$54)*Assumptions!$C$6+Assumptions!$C$54*Assumptions!C19)) | C16: =Volume!B20*Assumptions!$C$54*Assumptions!C19
A17: =Assumptions!A20 | B17: =Volume!B21*(1-((1-Assumptions!$C$54)*Assumptions!$C$6+Assumptions!$C$54*Assumptions!C20)) | C17: =Volume!B21*Assumptions!$C$54*Assumptions!C20
A18: =Assumptions!A21 | B18: =Volume!B22*(1-((1-Assumptions!$C$54)*Assumptions!$C$6+Assumptions!$C$54*Assumptions!C21)) | C18: =Volume!B22*Assumptions!$C$54*Assumptions!C21
A19: =Assumptions!A22 | B19: =Volume!B23*(1-((1-Assumptions!$C$54)*Assumptions!$C$6+Assumptions!$C$54*Assumptions!C22)) | C19: =Volume!B23*Assumptions!$C$54*Assumptions!C22
A20: =Assumptions!A23 | B20: =Volume!B24*(1-((1-Assumptions!$C$54)*Assumptions!$C$6+Assumptions!$C$54*Assumptions!C23)) | C20: =Volume!B24*Assumptions!$C$54*Assumptions!C23
A21: =Assumptions!A24 | B21: =Volume!B25*(1-((1-Assumptions!$C$54)*Assumptions!$C$6+Assumptions!$C$54*Assumptions!C24)) | C21: =Volume!B25*Assumptions!$C$54*Assumptions!C24
A22: Metered total | B22: =SUM(B15:B21) | C22: =SUM(C15:C21)
A24: Human payroll if metered | B24: =B22/Cost!B6*Cost!B5 | C24: Tickets ÷ capacity × loaded agent cost.
A25: Token bill if metered | B25: =Volume!E9*Assumptions!C54*Cost!B11 | C25: Fewer sessions, same price per session.
A26: Assist operating cost if metered | B26: =B25+Assumptions!C47+Assumptions!C48 | C26: Tokens fall. The owner does not.
A27: Total cost if metered | B27: =B24+B26
A28: Fee revenue | B28: =C22*Assumptions!C53 | C28: Closures × the fee. Failed sessions are not billed.
A29: Fee revenue minus Assist cost | B29: =B28-B26 | C29: Gross margin on the fee, before the tickets that come back.
A30: Margin on the fee | B30: =IF(B28=0,"n/a",(B28-B26)/B28) | C30: At ₹49 this is negative. The owner costs more than the fee collects.
A31: Net benefit vs doing nothing | B31: =(Cost!B23-B27)+B28 | C31: Payroll avoided, minus nothing, plus the fee.
A32: Free Assist net benefit, for comparison | B32: =B7 | C32: Same definition, no fee, higher adoption.
A33: Free beats the fee by | B33: =B32-B31 | C33: Positive means I would not turn the meter on.
A35: At the ₹49 input, fee revenue does not cover the playbook owner, so the margin on the fee is negative. Raise that blue cell until the margin turns positive and row 33 still loses to giving Assist away, because human tickets come back. Row 33 is the comparison.

Sheet Audit
A1: Monthly close
A2: Run the structural checks every time the sheet changes. Run the worked-example checks on the first Monday of the month with real numbers typed into the blue cells on Assumptions. A FAIL on wallet or send actions stops the rollout the same day. A FAIL on a playbook turns off that playbook's button and leaves the explanation in place.
A4: Structural — these should pass before anyone trusts a margin
A5: Check | B5: Result | C5: What it is looking at
A6: Business segments sum to 100% | B6: =IF(ABS(Assumptions!B14-1)<0.0001,"PASS","ALERT") | C6: Assumptions, who raises the queries.
A7: Issue shares sum to 100% | B7: =IF(ABS(Assumptions!B25-1)<0.0001,"PASS","ALERT") | C7: Assumptions, what the queries are.
A8: Month-3 roadmap matches the volume sheet | B8: =IF(Roadmap!B21="PASS","PASS","ALERT") | C8: Two formulas, one queue. They have to agree.
A9: Month-3 human tickets are below today | B9: =IF(Volume!G26<Volume!B14,"PASS","ALERT") | C9: If this fails, Assist is adding work.
A10: Monthly saving is positive | B10: =IF(Cost!B26>0,"PASS","ALERT") | C10: Fractional load. The number on Cost row 26.
A11: Free Assist beats the metered fee | B11: =IF(Billing!B33>0,"PASS","ALERT") | C11: If this fails, look again at the fee. The recommendation might be wrong.
A12: Token price inputs are present | B12: =IF(AND(Assumptions!C35>0,Assumptions!C37>0,Assumptions!C38>0),"PASS","ALERT") | C12: A zero price would fake the margin.
A14: This month's close — sample numbers until the first real month
A15: Check | B15: Result | C15: Rule
A16: OpenAI invoice vs logged token cost | B16: =IF(Assumptions!C68<=Cost!B13*(1+Assumptions!C63),"PASS","ALERT") | C16: Invoice ≤ logged cost × (1 + tolerance). Logs are Cost!B13. Invoice and tolerance are blue inputs.
A17: Repeat contact within 7 days | B17: =IF(Assumptions!C65<=Assumptions!C64,"PASS","ALERT") | C17: Observed rate ≤ the alert line. Over the line, that playbook loses its one-click button.
A18: Wrong one-click fixes in the sample of 30 | B18: =IF(Assumptions!C66=0,"PASS","ALERT") | C18: Any number above zero: turn the button off for that playbook the same day. Advice can stay.
A19: Wallet, plan, or send actions taken by Assist | B19: =IF(Assumptions!C67=0,"PASS","ALERT") | C19: Must be zero. This is a test in the product, not a sample. Non-zero stops rollout.
A21: Logged token cost the invoice is checked against | B21: =Cost!B13 | C21: Formula. Do not type over it. Type the invoice on Assumptions.
A23: What a person does on the first Monday
A24: Export Assist sessions: issue, tokens, resolved or handed off, and whether a ticket opened on the same issue within 7 days.
A25: Sum the tokens and compare with the OpenAI invoice. Type the invoice into the blue cell. The check above moves.
A26: Read 30 sessions marked resolved, stratified across the live playbooks. Count wrong one-click fixes, not clumsy wording.
A27: Confirm the automated test: Assist called no wallet, plan, or send endpoint. Type the count.
A28: Look at human tickets per 100 active businesses. If month 2 is not below month 1, do not add a playbook. Repair the one that is live.
A29: Do not bank the headcount saving until that rate has moved. The roster line on Cost is a ceiling for a reason.
A31: Alert destination: one channel the support lead already reads. A dashboard nobody opens is not an audit. The playbook owner is the person named on Assumptions. If that seat is empty, Assist should explain and should not edit.
